<?xml version="1.0" encoding="UTF-8"?>
<testng-results ignored="0" total="4" passed="2" failed="2" skipped="0">
  <reporter-output>
  </reporter-output>
  <suite started-at="2020-07-20T10:41:12 IST" name="Suite" finished-at="2020-07-20T10:41:13 IST" duration-ms="551">
    <groups>
    </groups>
    <test started-at="2020-07-20T10:41:12 IST" name="Test" finished-at="2020-07-20T10:41:13 IST" duration-ms="551">
      <class name="Extent.Adapter.Test2">
        <test-method signature="Test2_1()[pri:1, instance:Extent.Adapter.Test2@1356d4d4]" started-at="2020-07-20T10:41:13 IST" name="Test2_1" finished-at="2020-07-20T10:41:13 IST" duration-ms="3" status="PASS">
          <reporter-output>
          </reporter-output>
        </test-method> <!-- Test2_1 -->
        <test-method signature="Test2_2()[pri:2, instance:Extent.Adapter.Test2@1356d4d4]" started-at="2020-07-20T10:41:13 IST" name="Test2_2" finished-at="2020-07-20T10:41:13 IST" duration-ms="1" status="FAIL">
          <exception class="java.lang.AssertionError">
            <message>
              <![CDATA[expected [true] but found [false]]]>
            </message>
            <full-stacktrace>
              <![CDATA[java.lang.AssertionError: expected [true] but found [false]
at org.testng.Assert.fail(Assert.java:97)
at org.testng.Assert.failNotEquals(Assert.java:968)
at org.testng.Assert.assertTrue(Assert.java:43)
at org.testng.Assert.assertTrue(Assert.java:53)
at Extent.Adapter.Test2.Test2_2(Test2.java:15)
at java.base/jdk.internal.reflect.NativeMethodAccessorImpl.invoke0(Native Method)
at java.base/jdk.internal.reflect.NativeMethodAccessorImpl.invoke(NativeMethodAccessorImpl.java:62)
at java.base/jdk.internal.reflect.DelegatingMethodAccessorImpl.invoke(DelegatingMethodAccessorImpl.java:43)
at java.base/java.lang.reflect.Method.invoke(Method.java:566)
at org.testng.internal.MethodInvocationHelper.invokeMethod(MethodInvocationHelper.java:135)
at org.testng.internal.TestInvoker.invokeMethod(TestInvoker.java:598)
at org.testng.internal.TestInvoker.invokeTestMethod(TestInvoker.java:174)
at org.testng.internal.MethodRunner.runInSequence(MethodRunner.java:46)
at org.testng.internal.TestInvoker$MethodInvocationAgent.invoke(TestInvoker.java:821)
at org.testng.internal.TestInvoker.invokeTestMethods(TestInvoker.java:147)
at org.testng.internal.TestMethodWorker.invokeTestMethods(TestMethodWorker.java:146)
at org.testng.internal.TestMethodWorker.run(TestMethodWorker.java:128)
at java.base/java.util.ArrayList.forEach(ArrayList.java:1540)
at org.testng.TestRunner.privateRun(TestRunner.java:767)
at org.testng.TestRunner.run(TestRunner.java:588)
at org.testng.SuiteRunner.runTest(SuiteRunner.java:384)
at org.testng.SuiteRunner.runSequentially(SuiteRunner.java:378)
at org.testng.SuiteRunner.privateRun(SuiteRunner.java:337)
at org.testng.SuiteRunner.run(SuiteRunner.java:286)
at org.testng.SuiteRunnerWorker.runSuite(SuiteRunnerWorker.java:53)
at org.testng.SuiteRunnerWorker.run(SuiteRunnerWorker.java:96)
at org.testng.TestNG.runSuitesSequentially(TestNG.java:1214)
at org.testng.TestNG.runSuitesLocally(TestNG.java:1136)
at org.testng.TestNG.runSuites(TestNG.java:1066)
at org.testng.TestNG.run(TestNG.java:1034)
at org.testng.remote.AbstractRemoteTestNG.run(AbstractRemoteTestNG.java:115)
at org.testng.remote.RemoteTestNG.initAndRun(RemoteTestNG.java:251)
at org.testng.remote.RemoteTestNG.main(RemoteTestNG.java:77)
]]>
            </full-stacktrace>
          </exception> <!-- java.lang.AssertionError -->
          <reporter-output>
          </reporter-output>
        </test-method> <!-- Test2_2 -->
      </class> <!-- Extent.Adapter.Test2 -->
      <class name="Extent.Adapter.Test1">
        <test-method signature="Test1_1()[pri:1, instance:Extent.Adapter.Test1@55f616cf]" started-at="2020-07-20T10:41:13 IST" name="Test1_1" finished-at="2020-07-20T10:41:13 IST" duration-ms="21" status="PASS">
          <reporter-output>
          </reporter-output>
        </test-method> <!-- Test1_1 -->
        <test-method signature="Test1_2()[pri:2, instance:Extent.Adapter.Test1@55f616cf]" started-at="2020-07-20T10:41:13 IST" name="Test1_2" finished-at="2020-07-20T10:41:13 IST" duration-ms="3" status="FAIL">
          <exception class="java.lang.AssertionError">
            <message>
              <![CDATA[expected [true] but found [false]]]>
            </message>
            <full-stacktrace>
              <![CDATA[java.lang.AssertionError: expected [true] but found [false]
at org.testng.Assert.fail(Assert.java:97)
at org.testng.Assert.failNotEquals(Assert.java:968)
at org.testng.Assert.assertTrue(Assert.java:43)
at org.testng.Assert.assertTrue(Assert.java:53)
at Extent.Adapter.Test1.Test1_2(Test1.java:15)
at java.base/jdk.internal.reflect.NativeMethodAccessorImpl.invoke0(Native Method)
at java.base/jdk.internal.reflect.NativeMethodAccessorImpl.invoke(NativeMethodAccessorImpl.java:62)
at java.base/jdk.internal.reflect.DelegatingMethodAccessorImpl.invoke(DelegatingMethodAccessorImpl.java:43)
at java.base/java.lang.reflect.Method.invoke(Method.java:566)
at org.testng.internal.MethodInvocationHelper.invokeMethod(MethodInvocationHelper.java:135)
at org.testng.internal.TestInvoker.invokeMethod(TestInvoker.java:598)
at org.testng.internal.TestInvoker.invokeTestMethod(TestInvoker.java:174)
at org.testng.internal.MethodRunner.runInSequence(MethodRunner.java:46)
at org.testng.internal.TestInvoker$MethodInvocationAgent.invoke(TestInvoker.java:821)
at org.testng.internal.TestInvoker.invokeTestMethods(TestInvoker.java:147)
at org.testng.internal.TestMethodWorker.invokeTestMethods(TestMethodWorker.java:146)
at org.testng.internal.TestMethodWorker.run(TestMethodWorker.java:128)
at java.base/java.util.ArrayList.forEach(ArrayList.java:1540)
at org.testng.TestRunner.privateRun(TestRunner.java:767)
at org.testng.TestRunner.run(TestRunner.java:588)
at org.testng.SuiteRunner.runTest(SuiteRunner.java:384)
at org.testng.SuiteRunner.runSequentially(SuiteRunner.java:378)
at org.testng.SuiteRunner.privateRun(SuiteRunner.java:337)
at org.testng.SuiteRunner.run(SuiteRunner.java:286)
at org.testng.SuiteRunnerWorker.runSuite(SuiteRunnerWorker.java:53)
at org.testng.SuiteRunnerWorker.run(SuiteRunnerWorker.java:96)
at org.testng.TestNG.runSuitesSequentially(TestNG.java:1214)
at org.testng.TestNG.runSuitesLocally(TestNG.java:1136)
at org.testng.TestNG.runSuites(TestNG.java:1066)
at org.testng.TestNG.run(TestNG.java:1034)
at org.testng.remote.AbstractRemoteTestNG.run(AbstractRemoteTestNG.java:115)
at org.testng.remote.RemoteTestNG.initAndRun(RemoteTestNG.java:251)
at org.testng.remote.RemoteTestNG.main(RemoteTestNG.java:77)
]]>
            </full-stacktrace>
          </exception> <!-- java.lang.AssertionError -->
          <reporter-output>
          </reporter-output>
        </test-method> <!-- Test1_2 -->
      </class> <!-- Extent.Adapter.Test1 -->
    </test> <!-- Test -->
  </suite> <!-- Suite -->
</testng-results>
